{"uuid": "cdb2a8f3-a4f8-4159-a3c6-5fa0dcb43a71", "children": ["3c36a92b-07cb-45b3-9574-da5b2ab2b65f"], "befores": [{"name": "driver", "status": "broken", "statusDetails": {"message": "selenium.common.exceptions.SessionNotCreatedException: Message: session not created: probably user data directory is already in use, please specify a unique value for --user-data-dir argument, or don't use --user-data-dir\nStacktrace:\n\tGetHandleVerifier [0x0xa61af3+62339]\n\tGetHandleVerifier [0x0xa61b34+62404]\n\t(No symbol) [0x0x8a2123]\n\t(No symbol) [0x0x8d58b8]\n\t(No symbol) [0x0x8d11a9]\n\t(No symbol) [0x0x91ae77]\n\t(No symbol) [0x0x91a76a]\n\t(No symbol) [0x0x90f1b6]\n\t(No symbol) [0x0x8de7a2]\n\t(No symbol) [0x0x8df644]\n\tGetHandleVerifier [0x0xcd6683+2637587]\n\tGetHandleVerifier [0x0xcd1a8a+2618138]\n\tGetHandleVerifier [0x0xa8856a+220666]\n\tGetHandleVerifier [0x0xa78998+156200]\n\tGetHandleVerifier [0x0xa7f12d+182717]\n\tGetHandleVerifier [0x0xa69a38+94920]\n\tGetHandleVerifier [0x0xa69bc2+95314]\n\tGetHandleVerifier [0x0xa54d0a+9626]\n\tBaseThreadInitThunk [0x0x76625d49+25]\n\tRtlInitializeExceptionChain [0x0x7790d2fb+107]\n\tRtlGetAppContainerNamedObjectPath [0x0x7790d281+561]\n\n", "trace": "  File \"C:\\Users\\chere\\AppData\\Local\\Packages\\PythonSoftwareFoundation.Python.3.13_qbz5n2kfra8p0\\LocalCache\\local-packages\\Python313\\site-packages\\pluggy\\_callers.py\", line 38, in run_old_style_hookwrapper\n    res = yield\n          ^^^^^\n  File \"C:\\Users\\chere\\AppData\\Local\\Packages\\PythonSoftwareFoundation.Python.3.13_qbz5n2kfra8p0\\LocalCache\\local-packages\\Python313\\site-packages\\pluggy\\_callers.py\", line 139, in _multicall\n    teardown.throw(exception)\n    ~~~~~~~~~~~~~~^^^^^^^^^^^\n  File \"C:\\Users\\chere\\AppData\\Local\\Packages\\PythonSoftwareFoundation.Python.3.13_qbz5n2kfra8p0\\LocalCache\\local-packages\\Python313\\site-packages\\_pytest\\setuponly.py\", line 36, in pytest_fixture_setup\n    return (yield)\n            ^^^^^\n  File \"C:\\Users\\chere\\AppData\\Local\\Packages\\PythonSoftwareFoundation.Python.3.13_qbz5n2kfra8p0\\LocalCache\\local-packages\\Python313\\site-packages\\pluggy\\_callers.py\", line 121, in _multicall\n    res = hook_impl.function(*args)\n  File \"C:\\Users\\chere\\AppData\\Local\\Packages\\PythonSoftwareFoundation.Python.3.13_qbz5n2kfra8p0\\LocalCache\\local-packages\\Python313\\site-packages\\_pytest\\fixtures.py\", line 1195, in pytest_fixture_setup\n    result = call_fixture_func(fixturefunc, request, kwargs)\n  File \"C:\\Users\\chere\\AppData\\Local\\Packages\\PythonSoftwareFoundation.Python.3.13_qbz5n2kfra8p0\\LocalCache\\local-packages\\Python313\\site-packages\\_pytest\\fixtures.py\", line 922, in call_fixture_func\n    fixture_result = next(generator)\n  File \"C:\\Users\\chere\\Desktop\\final-project\\conftest.py\", line 12, in driver\n    driver = webdriver.Chrome(service=Service(ChromeDriverManager().install()), options=options)\n  File \"C:\\Users\\chere\\AppData\\Local\\Packages\\PythonSoftwareFoundation.Python.3.13_qbz5n2kfra8p0\\LocalCache\\local-packages\\Python313\\site-packages\\selenium\\webdriver\\chrome\\webdriver.py\", line 47, in __init__\n    super().__init__(\n    ~~~~~~~~~~~~~~~~^\n        browser_name=DesiredCapabilities.CHROME[\"browserName\"],\n        ^^^^^^^^^^^^^^^^^^^^^^^^^^^^^^^^^^^^^^^^^^^^^^^^^^^^^^^\n    ...<3 lines>...\n        keep_alive=keep_alive,\n        ^^^^^^^^^^^^^^^^^^^^^^\n    )\n    ^\n  File \"C:\\Users\\chere\\AppData\\Local\\Packages\\PythonSoftwareFoundation.Python.3.13_qbz5n2kfra8p0\\LocalCache\\local-packages\\Python313\\site-packages\\selenium\\webdriver\\chromium\\webdriver.py\", line 69, in __init__\n    super().__init__(command_executor=executor, options=options)\n    ~~~~~~~~~~~~~~~~^^^^^^^^^^^^^^^^^^^^^^^^^^^^^^^^^^^^^^^^^^^^\n  File \"C:\\Users\\chere\\AppData\\Local\\Packages\\PythonSoftwareFoundation.Python.3.13_qbz5n2kfra8p0\\LocalCache\\local-packages\\Python313\\site-packages\\selenium\\webdriver\\remote\\webdriver.py\", line 257, in __init__\n    self.start_session(capabilities)\n    ~~~~~~~~~~~~~~~~~~^^^^^^^^^^^^^^\n  File \"C:\\Users\\chere\\AppData\\Local\\Packages\\PythonSoftwareFoundation.Python.3.13_qbz5n2kfra8p0\\LocalCache\\local-packages\\Python313\\site-packages\\selenium\\webdriver\\remote\\webdriver.py\", line 356, in start_session\n    response = self.execute(Command.NEW_SESSION, caps)[\"value\"]\n               ~~~~~~~~~~~~^^^^^^^^^^^^^^^^^^^^^^^^^^^\n  File \"C:\\Users\\chere\\AppData\\Local\\Packages\\PythonSoftwareFoundation.Python.3.13_qbz5n2kfra8p0\\LocalCache\\local-packages\\Python313\\site-packages\\selenium\\webdriver\\remote\\webdriver.py\", line 447, in execute\n    self.error_handler.check_response(response)\n    ~~~~~~~~~~~~~~~~~~~~~~~~~~~~~~~~~^^^^^^^^^^\n  File \"C:\\Users\\chere\\AppData\\Local\\Packages\\PythonSoftwareFoundation.Python.3.13_qbz5n2kfra8p0\\LocalCache\\local-packages\\Python313\\site-packages\\selenium\\webdriver\\remote\\errorhandler.py\", line 232, in check_response\n    raise exception_class(message, screen, stacktrace)\n"}, "start": 1753717948840, "stop": 1753717954080}], "start": 1753717948840, "stop": 1753717954141}