{"uuid": "8dfd851f-7052-4a9f-af0a-dffffaadd3dd", "children": ["7dd40c64-be29-475d-91f1-1646c877e2af"], "befores": [{"name": "driver", "status": "broken", "statusDetails": {"message": "selenium.common.exceptions.NoSuchWindowException: Message: no such window: target window already closed\nfrom unknown error: web view not found\n  (Session info: chrome=138.0.7204.169)\nStacktrace:\n\tGetHandleVerifier [0x0xa61af3+62339]\n\tGetHandleVerifier [0x0xa61b34+62404]\n\t(No symbol) [0x0x8a2123]\n\t(No symbol) [0x0x880fc9]\n\t(No symbol) [0x0x915aee]\n\t(No symbol) [0x0x930089]\n\t(No symbol) [0x0x90f1b6]\n\t(No symbol) [0x0x8de7a2]\n\t(No symbol) [0x0x8df644]\n\tGetHandleVerifier [0x0xcd6683+2637587]\n\tGetHandleVerifier [0x0xcd1a8a+2618138]\n\tGetHandleVerifier [0x0xa8856a+220666]\n\tGetHandleVerifier [0x0xa78998+156200]\n\tGetHandleVerifier [0x0xa7f12d+182717]\n\tGetHandleVerifier [0x0xa69a38+94920]\n\tGetHandleVerifier [0x0xa69bc2+95314]\n\tGetHandleVerifier [0x0xa54d0a+9626]\n\tBaseThreadInitThunk [0x0x76625d49+25]\n\tRtlInitializeExceptionChain [0x0x7790d2fb+107]\n\tRtlGetAppContainerNamedObjectPath [0x0x7790d281+561]\n\n", "trace": "  File \"C:\\Users\\chere\\AppData\\Local\\Packages\\PythonSoftwareFoundation.Python.3.13_qbz5n2kfra8p0\\LocalCache\\local-packages\\Python313\\site-packages\\pluggy\\_callers.py\", line 38, in run_old_style_hookwrapper\n    res = yield\n          ^^^^^\n  File \"C:\\Users\\chere\\AppData\\Local\\Packages\\PythonSoftwareFoundation.Python.3.13_qbz5n2kfra8p0\\LocalCache\\local-packages\\Python313\\site-packages\\pluggy\\_callers.py\", line 139, in _multicall\n    teardown.throw(exception)\n    ~~~~~~~~~~~~~~^^^^^^^^^^^\n  File \"C:\\Users\\chere\\AppData\\Local\\Packages\\PythonSoftwareFoundation.Python.3.13_qbz5n2kfra8p0\\LocalCache\\local-packages\\Python313\\site-packages\\_pytest\\setuponly.py\", line 36, in pytest_fixture_setup\n    return (yield)\n            ^^^^^\n  File \"C:\\Users\\chere\\AppData\\Local\\Packages\\PythonSoftwareFoundation.Python.3.13_qbz5n2kfra8p0\\LocalCache\\local-packages\\Python313\\site-packages\\pluggy\\_callers.py\", line 121, in _multicall\n    res = hook_impl.function(*args)\n  File \"C:\\Users\\chere\\AppData\\Local\\Packages\\PythonSoftwareFoundation.Python.3.13_qbz5n2kfra8p0\\LocalCache\\local-packages\\Python313\\site-packages\\_pytest\\fixtures.py\", line 1195, in pytest_fixture_setup\n    result = call_fixture_func(fixturefunc, request, kwargs)\n  File \"C:\\Users\\chere\\AppData\\Local\\Packages\\PythonSoftwareFoundation.Python.3.13_qbz5n2kfra8p0\\LocalCache\\local-packages\\Python313\\site-packages\\_pytest\\fixtures.py\", line 922, in call_fixture_func\n    fixture_result = next(generator)\n  File \"C:\\Users\\chere\\Desktop\\final-project\\conftest.py\", line 48, in driver\n    driver.refresh()\n    ~~~~~~~~~~~~~~^^\n  File \"C:\\Users\\chere\\AppData\\Local\\Packages\\PythonSoftwareFoundation.Python.3.13_qbz5n2kfra8p0\\LocalCache\\local-packages\\Python313\\site-packages\\selenium\\webdriver\\remote\\webdriver.py\", line 716, in refresh\n    self.execute(Command.REFRESH)\n    ~~~~~~~~~~~~^^^^^^^^^^^^^^^^^\n  File \"C:\\Users\\chere\\AppData\\Local\\Packages\\PythonSoftwareFoundation.Python.3.13_qbz5n2kfra8p0\\LocalCache\\local-packages\\Python313\\site-packages\\selenium\\webdriver\\remote\\webdriver.py\", line 447, in execute\n    self.error_handler.check_response(response)\n    ~~~~~~~~~~~~~~~~~~~~~~~~~~~~~~~~~^^^^^^^^^^\n  File \"C:\\Users\\chere\\AppData\\Local\\Packages\\PythonSoftwareFoundation.Python.3.13_qbz5n2kfra8p0\\LocalCache\\local-packages\\Python313\\site-packages\\selenium\\webdriver\\remote\\errorhandler.py\", line 232, in check_response\n    raise exception_class(message, screen, stacktrace)\n"}, "start": 1753731460997, "stop": 1753731466463}], "start": 1753731460997, "stop": 1753731466532}